Workbook

Sheet Summary
A1: Abacus Financial Model v2 — Summary (Year 1-3)
A3: Revenue by Scenario
B4: Conservative | C4: Base Case | D4: Optimistic
A5: Year 1 Total Net Revenue (Months 1-12) | B5: =Conservative!B74 -> 4217.0676 | C5: ='Base Case'!B74 -> 15928.932 | D5: =Optimistic!B74 -> 64081.213
A6: Year 2 Total Net Revenue (Months 13-24) | B6: =Conservative!B75 -> 14921.212 | C6: ='Base Case'!B75 -> 73964.989 | D6: =Optimistic!B75 -> 401087.31
A7: Year 3 Total Net Revenue (Months 25-36) | B7: =Conservative!B76 -> 33162.627 | C7: ='Base Case'!B76 -> 185202.99 | D7: =Optimistic!B76 -> 1353535.3
A8: Month 36 Run-Rate (approx. monthly revenue exiting Year 3) | B8: =Conservative!B77 -> 3247.5428 | C8: ='Base Case'!B77 -> 19293.027 | D8: =Optimistic!B77 -> 154560.61
A9: — of which Program Revenue (lifetime + subscription) | B9: =Conservative!B78 -> 842.30712 | C9: ='Base Case'!B78 -> 4963.0931 | D9: =Optimistic!B78 -> 40597.214
A10: — of which Referral Revenue | B10: =Conservative!B79 -> 1405.0278 | C10: ='Base Case'!B79 -> 8537.2398 | D10: =Optimistic!B79 -> 74540.507
A11: — of which Add-On Revenue (virtual goods + course) | B11: =Conservative!B80 -> 248.807 | C11: ='Base Case'!B80 -> 2015.7372 | D11: =Optimistic!B80 -> 18102.695
A12: — of which B2B Employer-Benefit Revenue | B12: =Conservative!B81 -> 751.4009 | C12: ='Base Case'!B81 -> 3776.9568 | D12: =Optimistic!B81 -> 21320.194
A14: Target: $10,000/mo steady-state (carried forward from Regimen for comparability)
A16: What Would It Take to Hit $10,000/mo via C2C Alone? (Base Case unit economics; B2B is additive, not required)
A17: Monthly Revenue Target | B17: 10000
A18: Program: Blended Net Revenue per Converter (lifetime + sub LTV) | B18: ='Base Case'!B11*'Base Case'!B12*(1-'Base Case'!B15)*(1-'Base Case'!B14)+(1-'Base Case'!B11)*'Base Case'!B13*(1-'Base Case'!B14)/'Base Case'!B17 -> 64.416209
A19: Base Case Year-3 Install→Paid Conversion Rate | B19: ='Base Case'!B10 -> 0.035
A20: Referral: Revenue per Install (Year-3 rate × active lifetime) | B20: ='Base Case'!B18*'Base Case'!B22*'Base Case'!B23 -> 5.4
A21: Add-On: Revenue per Install (active lifetime × ARPU × (1-commission)) | B21: ='Base Case'!B18*'Base Case'!B24*(1-'Base Case'!B14) -> 1.275
A22: Blended Net Revenue per Install (Program + Referral + Add-On) | B22: =B19*B18+B20+B21 -> 8.9295673
A23: Required Steady-State Monthly Installs to Hit Target (C2C only) | B23: =B17/B22 -> 1119.8751
A25: Note: steady-state approximation, not a month-by-month projection — see the scenario sheets for the actual 36-month ramp. B2B revenue is deliberately excluded from this calc because it is a separate acquisition channel (employer contracts), not something that scales with consumer installs — see the scenario sheets for its actual contribution.
A27: Sensitivity: Steady-State Monthly Revenue by Installs × Conversion Rate (C2C only, excludes B2B)
A28: Installs \ Conversion | B28: 0.01 | C28: 0.02 | D28: 0.035 | E28: 0.05 | F28: 0.07 | G28: 0.1
A29: 500 | B29: =$A29*B$28*$B$18+$A29*$B$20+$A29*$B$21 -> 3659.581 | C29: =$A29*C$28*$B$18+$A29*$B$20+$A29*$B$21 -> 3981.6621 | D29: =$A29*D$28*$B$18+$A29*$B$20+$A29*$B$21 -> 4464.7837 | E29: =$A29*E$28*$B$18+$A29*$B$20+$A29*$B$21 -> 4947.9052 | F29: =$A29*F$28*$B$18+$A29*$B$20+$A29*$B$21 -> 5592.0673 | G29: =$A29*G$28*$B$18+$A29*$B$20+$A29*$B$21 -> 6558.3104
A30: 1000 | B30: =$A30*B$28*$B$18+$A30*$B$20+$A30*$B$21 -> 7319.1621 | C30: =$A30*C$28*$B$18+$A30*$B$20+$A30*$B$21 -> 7963.3242 | D30: =$A30*D$28*$B$18+$A30*$B$20+$A30*$B$21 -> 8929.5673 | E30: =$A30*E$28*$B$18+$A30*$B$20+$A30*$B$21 -> 9895.8104 | F30: =$A30*F$28*$B$18+$A30*$B$20+$A30*$B$21 -> 11184.135 | G30: =$A30*G$28*$B$18+$A30*$B$20+$A30*$B$21 -> 13116.621
A31: 2500 | B31: =$A31*B$28*$B$18+$A31*$B$20+$A31*$B$21 -> 18297.905 | C31: =$A31*C$28*$B$18+$A31*$B$20+$A31*$B$21 -> 19908.31 | D31: =$A31*D$28*$B$18+$A31*$B$20+$A31*$B$21 -> 22323.918 | E31: =$A31*E$28*$B$18+$A31*$B$20+$A31*$B$21 -> 24739.526 | F31: =$A31*F$28*$B$18+$A31*$B$20+$A31*$B$21 -> 27960.337 | G31: =$A31*G$28*$B$18+$A31*$B$20+$A31*$B$21 -> 32791.552
A32: 5000 | B32: =$A32*B$28*$B$18+$A32*$B$20+$A32*$B$21 -> 36595.81 | C32: =$A32*C$28*$B$18+$A32*$B$20+$A32*$B$21 -> 39816.621 | D32: =$A32*D$28*$B$18+$A32*$B$20+$A32*$B$21 -> 44647.837 | E32: =$A32*E$28*$B$18+$A32*$B$20+$A32*$B$21 -> 49479.052 | F32: =$A32*F$28*$B$18+$A32*$B$20+$A32*$B$21 -> 55920.673 | G32: =$A32*G$28*$B$18+$A32*$B$20+$A32*$B$21 -> 65583.104
A33: 10000 | B33: =$A33*B$28*$B$18+$A33*$B$20+$A33*$B$21 -> 73191.621 | C33: =$A33*C$28*$B$18+$A33*$B$20+$A33*$B$21 -> 79633.242 | D33: =$A33*D$28*$B$18+$A33*$B$20+$A33*$B$21 -> 89295.673 | E33: =$A33*E$28*$B$18+$A33*$B$20+$A33*$B$21 -> 98958.104 | F33: =$A33*F$28*$B$18+$A33*$B$20+$A33*$B$21 -> 111841.35 | G33: =$A33*G$28*$B$18+$A33*$B$20+$A33*$B$21 -> 131166.21
A34: 20000 | B34: =$A34*B$28*$B$18+$A34*$B$20+$A34*$B$21 -> 146383.24 | C34: =$A34*C$28*$B$18+$A34*$B$20+$A34*$B$21 -> 159266.48 | D34: =$A34*D$28*$B$18+$A34*$B$20+$A34*$B$21 -> 178591.35 | E34: =$A34*E$28*$B$18+$A34*$B$20+$A34*$B$21 -> 197916.21 | F34: =$A34*F$28*$B$18+$A34*$B$20+$A34*$B$21 -> 223682.69 | G34: =$A34*G$28*$B$18+$A34*$B$20+$A34*$B$21 -> 262332.42
A36: B2B Channel Contribution at Month 36 (Base Case)
A37: Active B2B Contracts (Month 36) | B37: ='Base Case'!B82 -> 53.956525
A38: Total B2B Seats (Month 36) | B38: ='Base Case'!B83 -> 1079.1305
A39: B2B Monthly Revenue (Month 36) | B39: ='Base Case'!B81 -> 3776.9568

Sheet Conservative
A1: Abacus Financial Model v2 — Conservative
A3: ASSUMPTIONS
A4: Starting Monthly Installs | B4: 200
A5: Install Growth Rate – Year 1 (monthly) | B5: 0.05
A6: Install Growth Rate – Year 2 (monthly) | B6: 0.03
A7: Install Growth Rate – Year 3 (monthly) | B7: 0.02
A8: Install → Paid Conversion – Year 1 | B8: 0.015
A9: Install → Paid Conversion – Year 2 | B9: 0.02
A10: Install → Paid Conversion – Year 3 | B10: 0.025
A11: % of Converters Choosing One-Time Lifetime (vs. Monthly) | B11: 0.5
A12: One-Time Lifetime Price | B12: 89.99
A13: Monthly Subscription Price | B13: 7.99
A14: Store Commission Rate (Apple/Google Small Business) | B14: 0.15
A15: Refund Rate – Lifetime Purchases | B15: 0.05
A16: Avg. Monthly Subscriber Lifetime (months) | B16: 6
A17: → Implied Monthly Subscriber Churn Rate | B17: =1/B16 -> 0.16666667
A18: Avg. Active-User Lifetime (months, drives referral + add-on revenue) | B18: 12
A19: → Implied Monthly Active-User Decay Rate | B19: =1/B18 -> 0.083333333
A20: % of Active Users Completing a Financial-Product Referral – Y1 | B20: 0.003
A21: % of Active Users Completing a Financial-Product Referral – Y2 | B21: 0.005
A22: % of Active Users Completing a Financial-Product Referral – Y3 | B22: 0.008
A23: Average Referral Bounty (paid directly, no store commission) | B23: 30
A24: Add-On ARPU per Active User per Month (virtual goods + paid course, blended) | B24: 0.05
A25: B2B: First Month Employer Channel Goes Live | B25: 15
A26: B2B: New Employer Contracts in First Live Month | B26: 1
A27: B2B: Monthly Growth Rate of New-Contract Pace | B27: 0.02
A28: B2B: Avg. Employees (Seats) per Contract | B28: 15
A29: B2B: Price per Seat per Month | B29: 3
A30: B2B: Avg. Contract Lifetime (months) | B30: 18
A31: → Implied Monthly Contract Attrition Rate | B31: =1/B30 -> 0.055555556
A33: Sources: 15% commission = Apple/Google Small Business Program (<$1M/yr). Referral bounty and B2B seat revenue are paid/invoiced directly (not IAP), so NOT subject to store commission; add-on ARPU (virtual goods + paid course) IS sold via IAP so store commission is applied to it in the revenue formula below. B2B pricing anchored to real SMB financial-wellness self-serve benchmarks ($3-5/employee/month, e.g. basic digital wellness platforms); add-on ARPU anchored to Duolingo's real IAP+virtual-goods mix (~5% of revenue) but scaled down conservatively since Abacus has no large free/ad-supported base to cross-sell against. B2B channel start month is later than the C2C launch — modeled as needing a live product with organic traction before a self-serve employer-benefit funnel is credible. All rates are planning assumptions, not observed data.
A35: 36-MONTH PROJECTION
A36: Month | B36: Year | C36: New Installs | D36: New Paid Converters | E36: New Lifetime Buyers | F36: New Monthly Subs | G36: Active Monthly Subs | H36: Active User Base | I36: Lifetime Rev (net) | J36: Subscription Rev (net) | K36: Referral Rev | L36: Add-On Rev (net) | M36: New B2B Contracts | N36: Active B2B Contracts | O36: B2B Seats | P36: B2B Rev | Q36: Total Net Revenue | R36: Cumulative Revenue
A37: 1 | B37: =ROUNDUP(A37/12,0) -> 1 | C37: =$B$4 -> 200 | D37: =C37*CHOOSE(B37,$B$8,$B$9,$B$10) -> 3 | E37: =D37*$B$11 -> 1.5 | F37: =D37*(1-$B$11) -> 1.5 | G37: =F37 -> 1.5 | H37: =C37 -> 200 | I37: =E37*$B$12*(1-$B$15)*(1-$B$14) -> 109.00039 | J37: =G37*$B$13*(1-$B$14) -> 10.18725 | K37: =H37*CHOOSE(B37,$B$20,$B$21,$B$22)*$B$23 -> 18 | L37: =H37*$B$24*(1-$B$14) -> 8.5 | M37: =IF(A37<$B$25,0,IF(A37=$B$25,$B$26,M36*(1+$B$27))) -> 0 | N37: =M37 -> 0 | O37: =N37*$B$28 -> 0 | P37: =O37*$B$29 -> 0 | Q37: =I37+J37+K37+L37+P37 -> 145.68764 | R37: =Q37 -> 145.68764
A38: 2 | B38: =ROUNDUP(A38/12,0) -> 1 | C38: =C37*(1+CHOOSE(B38,$B$5,$B$6,$B$7)) -> 210 | D38: =C38*CHOOSE(B38,$B$8,$B$9,$B$10) -> 3.15 | E38: =D38*$B$11 -> 1.575 | F38: =D38*(1-$B$11) -> 1.575 | G38: =G37*(1-$B$17)+F38 -> 2.825 | H38: =H37*(1-$B$19)+C38 -> 393.33333 | I38: =E38*$B$12*(1-$B$15)*(1-$B$14) -> 114.45041 | J38: =G38*$B$13*(1-$B$14) -> 19.185987 | K38: =H38*CHOOSE(B38,$B$20,$B$21,$B$22)*$B$23 -> 35.4 | L38: =H38*$B$24*(1-$B$14) -> 16.716667 | M38: =IF(A38<$B$25,0,IF(A38=$B$25,$B$26,M37*(1+$B$27))) -> 0 | N38: =N37*(1-$B$31)+M38 -> 0 | O38: =N38*$B$28 -> 0 | P38: =O38*$B$29 -> 0 | Q38: =I38+J38+K38+L38+P38 -> 185.75306 | R38: =R37+Q38 -> 331.4407
A39: 3 | B39: =ROUNDUP(A39/12,0) -> 1 | C39: =C38*(1+CHOOSE(B39,$B$5,$B$6,$B$7)) -> 220.5 | D39: =C39*CHOOSE(B39,$B$8,$B$9,$B$10) -> 3.3075 | E39: =D39*$B$11 -> 1.65375 | F39: =D39*(1-$B$11) -> 1.65375 | G39: =G38*(1-$B$17)+F39 -> 4.0079167 | H39: =H38*(1-$B$19)+C39 -> 581.05556 | I39: =E39*$B$12*(1-$B$15)*(1-$B$14) -> 120.17293 | J39: =G39*$B$13*(1-$B$14) -> 27.219766 | K39: =H39*CHOOSE(B39,$B$20,$B$21,$B$22)*$B$23 -> 52.295 | L39: =H39*$B$24*(1-$B$14) -> 24.694861 | M39: =IF(A39<$B$25,0,IF(A39=$B$25,$B$26,M38*(1+$B$27))) -> 0 | N39: =N38*(1-$B$31)+M39 -> 0 | O39: =N39*$B$28 -> 0 | P39: =O39*$B$29 -> 0 | Q39: =I39+J39+K39+L39+P39 -> 224.38255 | R39: =R38+Q39 -> 555.82325
A40: 4 | B40: =ROUNDUP(A40/12,0) -> 1 | C40: =C39*(1+CHOOSE(B40,$B$5,$B$6,$B$7)) -> 231.525 | D40: =C40*CHOOSE(B40,$B$8,$B$9,$B$10) -> 3.472875 | E40: =D40*$B$11 -> 1.7364375 | F40: =D40*(1-$B$11) -> 1.7364375 | G40: =G39*(1-$B$17)+F40 -> 5.0763681 | H40: =H39*(1-$B$19)+C40 -> 764.15926 | I40: =E40*$B$12*(1-$B$15)*(1-$B$14) -> 126.18157 | J40: =G40*$B$13*(1-$B$14) -> 34.476154 | K40: =H40*CHOOSE(B40,$B$20,$B$21,$B$22)*$B$23 -> 68.774333 | L40: =H40*$B$24*(1-$B$14) -> 32.476769 | M40: =IF(A40<$B$25,0,IF(A40=$B$25,$B$26,M39*(1+$B$27))) -> 0 | N40: =N39*(1-$B$31)+M40 -> 0 | O40: =N40*$B$28 -> 0 | P40: =O40*$B$29 -> 0 | Q40: =I40+J40+K40+L40+P40 -> 261.90883 | R40: =R39+Q40 -> 817.73208
A41: 5 | B41: =ROUNDUP(A41/12,0) -> 1 | C41: =C40*(1+CHOOSE(B41,$B$5,$B$6,$B$7)) -> 243.10125 | D41: =C41*CHOOSE(B41,$B$8,$B$9,$B$10) -> 3.6465187 | E41: =D41*$B$11 -> 1.8232594 | F41: =D41*(1-$B$11) -> 1.8232594 | G41: =G40*(1-$B$17)+F41 -> 6.0535661 | H41: =H40*(1-$B$19)+C41 -> 943.58057 | I41: =E41*$B$12*(1-$B$15)*(1-$B$14) -> 132.49065 | J41: =G41*$B$13*(1-$B$14) -> 41.112794 | K41: =H41*CHOOSE(B41,$B$20,$B$21,$B$22)*$B$23 -> 84.922251 | L41: =H41*$B$24*(1-$B$14) -> 40.102174 | M41: =IF(A41<$B$25,0,IF(A41=$B$25,$B$26,M40*(1+$B$27))) -> 0 | N41: =N40*(1-$B$31)+M41 -> 0 | O41: =N41*$B$28 -> 0 | P41: =O41*$B$29 -> 0 | Q41: =I41+J41+K41+L41+P41 -> 298.62787 | R41: =R40+Q41 -> 1116.36
A42: 6 | B42: =ROUNDUP(A42/12,0) -> 1 | C42: =C41*(1+CHOOSE(B42,$B$5,$B$6,$B$7)) -> 255.25631 | D42: =C42*CHOOSE(B42,$B$8,$B$9,$B$10) -> 3.8288447 | E42: =D42*$B$11 -> 1.9144223 | F42: =D42*(1-$B$11) -> 1.9144223 | G42: =G41*(1-$B$17)+F42 -> 6.9590608 | H42: =H41*(1-$B$19)+C42 -> 1120.2052 | I42: =E42*$B$12*(1-$B$15)*(1-$B$14) -> 139.11518 | J42: =G42*$B$13*(1-$B$14) -> 47.262461 | K42: =H42*CHOOSE(B42,$B$20,$B$21,$B$22)*$B$23 -> 100.81847 | L42: =H42*$B$24*(1-$B$14) -> 47.60872 | M42: =IF(A42<$B$25,0,IF(A42=$B$25,$B$26,M41*(1+$B$27))) -> 0 | N42: =N41*(1-$B$31)+M42 -> 0 | O42: =N42*$B$28 -> 0 | P42: =O42*$B$29 -> 0 | Q42: =I42+J42+K42+L42+P42 -> 334.80483 | R42: =R41+Q42 -> 1451.1648
A43: 7 | B43: =ROUNDUP(A43/12,0) -> 1 | C43: =C42*(1+CHOOSE(B43,$B$5,$B$6,$B$7)) -> 268.01913 | D43: =C43*CHOOSE(B43,$B$8,$B$9,$B$10) -> 4.0202869 | E43: =D43*$B$11 -> 2.0101435 | F43: =D43*(1-$B$11) -> 2.0101435 | G43: =G42*(1-$B$17)+F43 -> 7.8093608 | H43: =H42*(1-$B$19)+C43 -> 1294.8739 | I43: =E43*$B$12*(1-$B$15)*(1-$B$14) -> 146.07094 | J43: =G43*$B$13*(1-$B$14) -> 53.037274 | K43: =H43*CHOOSE(B43,$B$20,$B$21,$B$22)*$B$23 -> 116.53865 | L43: =H43*$B$24*(1-$B$14) -> 55.032139 | M43: =IF(A43<$B$25,0,IF(A43=$B$25,$B$26,M42*(1+$B$27))) -> 0 | N43: =N42*(1-$B$31)+M43 -> 0 | O43: =N43*$B$28 -> 0 | P43: =O43*$B$29 -> 0 | Q43: =I43+J43+K43+L43+P43 -> 370.679 | R43: =R42+Q43 -> 1821.8438
...

Sheet Base Case
A1: Abacus Financial Model v2 — Base Case
A3: ASSUMPTIONS
A4: Starting Monthly Installs | B4: 400
A5: Install Growth Rate – Year 1 (monthly) | B5: 0.08
A6: Install Growth Rate – Year 2 (monthly) | B6: 0.05
A7: Install Growth Rate – Year 3 (monthly) | B7: 0.03
A8: Install → Paid Conversion – Year 1 | B8: 0.02
A9: Install → Paid Conversion – Year 2 | B9: 0.028
A10: Install → Paid Conversion – Year 3 | B10: 0.035
A11: % of Converters Choosing One-Time Lifetime (vs. Monthly) | B11: 0.55
A12: One-Time Lifetime Price | B12: 89.99
A13: Monthly Subscription Price | B13: 7.99
A14: Store Commission Rate (Apple/Google Small Business) | B14: 0.15
A15: Refund Rate – Lifetime Purchases | B15: 0.05
A16: Avg. Monthly Subscriber Lifetime (months) | B16: 8
A17: → Implied Monthly Subscriber Churn Rate | B17: =1/B16 -> 0.125
A18: Avg. Active-User Lifetime (months, drives referral + add-on revenue) | B18: 15
A19: → Implied Monthly Active-User Decay Rate | B19: =1/B18 -> 0.066666667
A20: % of Active Users Completing a Financial-Product Referral – Y1 | B20: 0.005
A21: % of Active Users Completing a Financial-Product Referral – Y2 | B21: 0.008
A22: % of Active Users Completing a Financial-Product Referral – Y3 | B22: 0.012
A23: Average Referral Bounty (paid directly, no store commission) | B23: 30
A24: Add-On ARPU per Active User per Month (virtual goods + paid course, blended) | B24: 0.1
A25: B2B: First Month Employer Channel Goes Live | B25: 13
A26: B2B: New Employer Contracts in First Live Month | B26: 2
A27: B2B: Monthly Growth Rate of New-Contract Pace | B27: 0.04
A28: B2B: Avg. Employees (Seats) per Contract | B28: 20
A29: B2B: Price per Seat per Month | B29: 3.5
A30: B2B: Avg. Contract Lifetime (months) | B30: 24
A31: → Implied Monthly Contract Attrition Rate | B31: =1/B30 -> 0.041666667
A33: Sources: 15% commission = Apple/Google Small Business Program (<$1M/yr). Referral bounty and B2B seat revenue are paid/invoiced directly (not IAP), so NOT subject to store commission; add-on ARPU (virtual goods + paid course) IS sold via IAP so store commission is applied to it in the revenue formula below. B2B pricing anchored to real SMB financial-wellness self-serve benchmarks ($3-5/employee/month, e.g. basic digital wellness platforms); add-on ARPU anchored to Duolingo's real IAP+virtual-goods mix (~5% of revenue) but scaled down conservatively since Abacus has no large free/ad-supported base to cross-sell against. B2B channel start month is later than the C2C launch — modeled as needing a live product with organic traction before a self-serve employer-benefit funnel is credible. All rates are planning assumptions, not observed data.
A35: 36-MONTH PROJECTION
A36: Month | B36: Year | C36: New Installs | D36: New Paid Converters | E36: New Lifetime Buyers | F36: New Monthly Subs | G36: Active Monthly Subs | H36: Active User Base | I36: Lifetime Rev (net) | J36: Subscription Rev (net) | K36: Referral Rev | L36: Add-On Rev (net) | M36: New B2B Contracts | N36: Active B2B Contracts | O36: B2B Seats | P36: B2B Rev | Q36: Total Net Revenue | R36: Cumulative Revenue
A37: 1 | B37: =ROUNDUP(A37/12,0) -> 1 | C37: =$B$4 -> 400 | D37: =C37*CHOOSE(B37,$B$8,$B$9,$B$10) -> 8 | E37: =D37*$B$11 -> 4.4 | F37: =D37*(1-$B$11) -> 3.6 | G37: =F37 -> 3.6 | H37: =C37 -> 400 | I37: =E37*$B$12*(1-$B$15)*(1-$B$14) -> 319.73447 | J37: =G37*$B$13*(1-$B$14) -> 24.4494 | K37: =H37*CHOOSE(B37,$B$20,$B$21,$B$22)*$B$23 -> 60 | L37: =H37*$B$24*(1-$B$14) -> 34 | M37: =IF(A37<$B$25,0,IF(A37=$B$25,$B$26,M36*(1+$B$27))) -> 0 | N37: =M37 -> 0 | O37: =N37*$B$28 -> 0 | P37: =O37*$B$29 -> 0 | Q37: =I37+J37+K37+L37+P37 -> 438.18387 | R37: =Q37 -> 438.18387
A38: 2 | B38: =ROUNDUP(A38/12,0) -> 1 | C38: =C37*(1+CHOOSE(B38,$B$5,$B$6,$B$7)) -> 432 | D38: =C38*CHOOSE(B38,$B$8,$B$9,$B$10) -> 8.64 | E38: =D38*$B$11 -> 4.752 | F38: =D38*(1-$B$11) -> 3.888 | G38: =G37*(1-$B$17)+F38 -> 7.038 | H38: =H37*(1-$B$19)+C38 -> 805.33333 | I38: =E38*$B$12*(1-$B$15)*(1-$B$14) -> 345.31323 | J38: =G38*$B$13*(1-$B$14) -> 47.798577 | K38: =H38*CHOOSE(B38,$B$20,$B$21,$B$22)*$B$23 -> 120.8 | L38: =H38*$B$24*(1-$B$14) -> 68.453333 | M38: =IF(A38<$B$25,0,IF(A38=$B$25,$B$26,M37*(1+$B$27))) -> 0 | N38: =N37*(1-$B$31)+M38 -> 0 | O38: =N38*$B$28 -> 0 | P38: =O38*$B$29 -> 0 | Q38: =I38+J38+K38+L38+P38 -> 582.36514 | R38: =R37+Q38 -> 1020.549
A39: 3 | B39: =ROUNDUP(A39/12,0) -> 1 | C39: =C38*(1+CHOOSE(B39,$B$5,$B$6,$B$7)) -> 466.56 | D39: =C39*CHOOSE(B39,$B$8,$B$9,$B$10) -> 9.3312 | E39: =D39*$B$11 -> 5.13216 | F39: =D39*(1-$B$11) -> 4.19904 | G39: =G38*(1-$B$17)+F39 -> 10.35729 | H39: =H38*(1-$B$19)+C39 -> 1218.2044 | I39: =E39*$B$12*(1-$B$15)*(1-$B$14) -> 372.93829 | J39: =G39*$B$13*(1-$B$14) -> 70.341535 | K39: =H39*CHOOSE(B39,$B$20,$B$21,$B$22)*$B$23 -> 182.73067 | L39: =H39*$B$24*(1-$B$14) -> 103.54738 | M39: =IF(A39<$B$25,0,IF(A39=$B$25,$B$26,M38*(1+$B$27))) -> 0 | N39: =N38*(1-$B$31)+M39 -> 0 | O39: =N39*$B$28 -> 0 | P39: =O39*$B$29 -> 0 | Q39: =I39+J39+K39+L39+P39 -> 729.55787 | R39: =R38+Q39 -> 1750.1069
A40: 4 | B40: =ROUNDUP(A40/12,0) -> 1 | C40: =C39*(1+CHOOSE(B40,$B$5,$B$6,$B$7)) -> 503.8848 | D40: =C40*CHOOSE(B40,$B$8,$B$9,$B$10) -> 10.077696 | E40: =D40*$B$11 -> 5.5427328 | F40: =D40*(1-$B$11) -> 4.5349632 | G40: =G39*(1-$B$17)+F40 -> 13.597592 | H40: =H39*(1-$B$19)+C40 -> 1640.8756 | I40: =E40*$B$12*(1-$B$15)*(1-$B$14) -> 402.77335 | J40: =G40*$B$13*(1-$B$14) -> 92.348046 | K40: =H40*CHOOSE(B40,$B$20,$B$21,$B$22)*$B$23 -> 246.13134 | L40: =H40*$B$24*(1-$B$14) -> 139.47443 | M40: =IF(A40<$B$25,0,IF(A40=$B$25,$B$26,M39*(1+$B$27))) -> 0 | N40: =N39*(1-$B$31)+M40 -> 0 | O40: =N40*$B$28 -> 0 | P40: =O40*$B$29 -> 0 | Q40: =I40+J40+K40+L40+P40 -> 880.72716 | R40: =R39+Q40 -> 2630.834
A41: 5 | B41: =ROUNDUP(A41/12,0) -> 1 | C41: =C40*(1+CHOOSE(B41,$B$5,$B$6,$B$7)) -> 544.19558 | D41: =C41*CHOOSE(B41,$B$8,$B$9,$B$10) -> 10.883912 | E41: =D41*$B$11 -> 5.9861514 | F41: =D41*(1-$B$11) -> 4.8977603 | G41: =G40*(1-$B$17)+F41 -> 16.795653 | H41: =H40*(1-$B$19)+C41 -> 2075.6795 | I41: =E41*$B$12*(1-$B$15)*(1-$B$14) -> 434.99522 | J41: =G41*$B$13*(1-$B$14) -> 114.06768 | K41: =H41*CHOOSE(B41,$B$20,$B$21,$B$22)*$B$23 -> 311.35192 | L41: =H41*$B$24*(1-$B$14) -> 176.43276 | M41: =IF(A41<$B$25,0,IF(A41=$B$25,$B$26,M40*(1+$B$27))) -> 0 | N41: =N40*(1-$B$31)+M41 -> 0 | O41: =N41*$B$28 -> 0 | P41: =O41*$B$29 -> 0 | Q41: =I41+J41+K41+L41+P41 -> 1036.8476 | R41: =R40+Q41 -> 3667.6816
A42: 6 | B42: =ROUNDUP(A42/12,0) -> 1 | C42: =C41*(1+CHOOSE(B42,$B$5,$B$6,$B$7)) -> 587.73123 | D42: =C42*CHOOSE(B42,$B$8,$B$9,$B$10) -> 11.754625 | E42: =D42*$B$11 -> 6.4650435 | F42: =D42*(1-$B$11) -> 5.2895811 | G42: =G41*(1-$B$17)+F42 -> 19.985778 | H42: =H41*(1-$B$19)+C42 -> 2525.0321 | I42: =E42*$B$12*(1-$B$15)*(1-$B$14) -> 469.79483 | J42: =G42*$B$13*(1-$B$14) -> 135.73341 | K42: =H42*CHOOSE(B42,$B$20,$B$21,$B$22)*$B$23 -> 378.75481 | L42: =H42*$B$24*(1-$B$14) -> 214.62773 | M42: =IF(A42<$B$25,0,IF(A42=$B$25,$B$26,M41*(1+$B$27))) -> 0 | N42: =N41*(1-$B$31)+M42 -> 0 | O42: =N42*$B$28 -> 0 | P42: =O42*$B$29 -> 0 | Q42: =I42+J42+K42+L42+P42 -> 1198.9108 | R42: =R41+Q42 -> 4866.5924
A43: 7 | B43: =ROUNDUP(A43/12,0) -> 1 | C43: =C42*(1+CHOOSE(B43,$B$5,$B$6,$B$7)) -> 634.74973 | D43: =C43*CHOOSE(B43,$B$8,$B$9,$B$10) -> 12.694995 | E43: =D43*$B$11 -> 6.982247 | F43: =D43*(1-$B$11) -> 5.7127476 | G43: =G42*(1-$B$17)+F43 -> 23.200303 | H43: =H42*(1-$B$19)+C43 -> 2991.4463 | I43: =E43*$B$12*(1-$B$15)*(1-$B$14) -> 507.37842 | J43: =G43*$B$13*(1-$B$14) -> 157.56486 | K43: =H43*CHOOSE(B43,$B$20,$B$21,$B$22)*$B$23 -> 448.71695 | L43: =H43*$B$24*(1-$B$14) -> 254.27294 | M43: =IF(A43<$B$25,0,IF(A43=$B$25,$B$26,M42*(1+$B$27))) -> 0 | N43: =N42*(1-$B$31)+M43 -> 0 | O43: =N43*$B$28 -> 0 | P43: =O43*$B$29 -> 0 | Q43: =I43+J43+K43+L43+P43 -> 1367.9332 | R43: =R42+Q43 -> 6234.5256
...

Sheet Optimistic
A1: Abacus Financial Model v2 — Optimistic
A3: ASSUMPTIONS
A4: Starting Monthly Installs | B4: 700
A5: Install Growth Rate – Year 1 (monthly) | B5: 0.12
A6: Install Growth Rate – Year 2 (monthly) | B6: 0.08
A7: Install Growth Rate – Year 3 (monthly) | B7: 0.05
A8: Install → Paid Conversion – Year 1 | B8: 0.03
A9: Install → Paid Conversion – Year 2 | B9: 0.045
A10: Install → Paid Conversion – Year 3 | B10: 0.06
A11: % of Converters Choosing One-Time Lifetime (vs. Monthly) | B11: 0.6
A12: One-Time Lifetime Price | B12: 89.99
A13: Monthly Subscription Price | B13: 7.99
A14: Store Commission Rate (Apple/Google Small Business) | B14: 0.15
A15: Refund Rate – Lifetime Purchases | B15: 0.05
A16: Avg. Monthly Subscriber Lifetime (months) | B16: 10
A17: → Implied Monthly Subscriber Churn Rate | B17: =1/B16 -> 0.1
A18: Avg. Active-User Lifetime (months, drives referral + add-on revenue) | B18: 20
A19: → Implied Monthly Active-User Decay Rate | B19: =1/B18 -> 0.05
A20: % of Active Users Completing a Financial-Product Referral – Y1 | B20: 0.008
A21: % of Active Users Completing a Financial-Product Referral – Y2 | B21: 0.012
A22: % of Active Users Completing a Financial-Product Referral – Y3 | B22: 0.02
A23: Average Referral Bounty (paid directly, no store commission) | B23: 35
A24: Add-On ARPU per Active User per Month (virtual goods + paid course, blended) | B24: 0.2
A25: B2B: First Month Employer Channel Goes Live | B25: 10
A26: B2B: New Employer Contracts in First Live Month | B26: 4
A27: B2B: Monthly Growth Rate of New-Contract Pace | B27: 0.06
A28: B2B: Avg. Employees (Seats) per Contract | B28: 25
A29: B2B: Price per Seat per Month | B29: 4.5
A30: B2B: Avg. Contract Lifetime (months) | B30: 30
A31: → Implied Monthly Contract Attrition Rate | B31: =1/B30 -> 0.033333333
A33: Sources: 15% commission = Apple/Google Small Business Program (<$1M/yr). Referral bounty and B2B seat revenue are paid/invoiced directly (not IAP), so NOT subject to store commission; add-on ARPU (virtual goods + paid course) IS sold via IAP so store commission is applied to it in the revenue formula below. B2B pricing anchored to real SMB financial-wellness self-serve benchmarks ($3-5/employee/month, e.g. basic digital wellness platforms); add-on ARPU anchored to Duolingo's real IAP+virtual-goods mix (~5% of revenue) but scaled down conservatively since Abacus has no large free/ad-supported base to cross-sell against. B2B channel start month is later than the C2C launch — modeled as needing a live product with organic traction before a self-serve employer-benefit funnel is credible. All rates are planning assumptions, not observed data.
A35: 36-MONTH PROJECTION
A36: Month | B36: Year | C36: New Installs | D36: New Paid Converters | E36: New Lifetime Buyers | F36: New Monthly Subs | G36: Active Monthly Subs | H36: Active User Base | I36: Lifetime Rev (net) | J36: Subscription Rev (net) | K36: Referral Rev | L36: Add-On Rev (net) | M36: New B2B Contracts | N36: Active B2B Contracts | O36: B2B Seats | P36: B2B Rev | Q36: Total Net Revenue | R36: Cumulative Revenue
A37: 1 | B37: =ROUNDUP(A37/12,0) -> 1 | C37: =$B$4 -> 700 | D37: =C37*CHOOSE(B37,$B$8,$B$9,$B$10) -> 21 | E37: =D37*$B$11 -> 12.6 | F37: =D37*(1-$B$11) -> 8.4 | G37: =F37 -> 8.4 | H37: =C37 -> 700 | I37: =E37*$B$12*(1-$B$15)*(1-$B$14) -> 915.60325 | J37: =G37*$B$13*(1-$B$14) -> 57.0486 | K37: =H37*CHOOSE(B37,$B$20,$B$21,$B$22)*$B$23 -> 196 | L37: =H37*$B$24*(1-$B$14) -> 119 | M37: =IF(A37<$B$25,0,IF(A37=$B$25,$B$26,M36*(1+$B$27))) -> 0 | N37: =M37 -> 0 | O37: =N37*$B$28 -> 0 | P37: =O37*$B$29 -> 0 | Q37: =I37+J37+K37+L37+P37 -> 1287.6519 | R37: =Q37 -> 1287.6519
A38: 2 | B38: =ROUNDUP(A38/12,0) -> 1 | C38: =C37*(1+CHOOSE(B38,$B$5,$B$6,$B$7)) -> 784 | D38: =C38*CHOOSE(B38,$B$8,$B$9,$B$10) -> 23.52 | E38: =D38*$B$11 -> 14.112 | F38: =D38*(1-$B$11) -> 9.408 | G38: =G37*(1-$B$17)+F38 -> 16.968 | H38: =H37*(1-$B$19)+C38 -> 1449 | I38: =E38*$B$12*(1-$B$15)*(1-$B$14) -> 1025.4756 | J38: =G38*$B$13*(1-$B$14) -> 115.23817 | K38: =H38*CHOOSE(B38,$B$20,$B$21,$B$22)*$B$23 -> 405.72 | L38: =H38*$B$24*(1-$B$14) -> 246.33 | M38: =IF(A38<$B$25,0,IF(A38=$B$25,$B$26,M37*(1+$B$27))) -> 0 | N38: =N37*(1-$B$31)+M38 -> 0 | O38: =N38*$B$28 -> 0 | P38: =O38*$B$29 -> 0 | Q38: =I38+J38+K38+L38+P38 -> 1792.7638 | R38: =R37+Q38 -> 3080.4157
A39: 3 | B39: =ROUNDUP(A39/12,0) -> 1 | C39: =C38*(1+CHOOSE(B39,$B$5,$B$6,$B$7)) -> 878.08 | D39: =C39*CHOOSE(B39,$B$8,$B$9,$B$10) -> 26.3424 | E39: =D39*$B$11 -> 15.80544 | F39: =D39*(1-$B$11) -> 10.53696 | G39: =G38*(1-$B$17)+F39 -> 25.80816 | H39: =H38*(1-$B$19)+C39 -> 2254.63 | I39: =E39*$B$12*(1-$B$15)*(1-$B$14) -> 1148.5327 | J39: =G39*$B$13*(1-$B$14) -> 175.27612 | K39: =H39*CHOOSE(B39,$B$20,$B$21,$B$22)*$B$23 -> 631.2964 | L39: =H39*$B$24*(1-$B$14) -> 383.2871 | M39: =IF(A39<$B$25,0,IF(A39=$B$25,$B$26,M38*(1+$B$27))) -> 0 | N39: =N38*(1-$B$31)+M39 -> 0 | O39: =N39*$B$28 -> 0 | P39: =O39*$B$29 -> 0 | Q39: =I39+J39+K39+L39+P39 -> 2338.3923 | R39: =R38+Q39 -> 5418.808
A40: 4 | B40: =ROUNDUP(A40/12,0) -> 1 | C40: =C39*(1+CHOOSE(B40,$B$5,$B$6,$B$7)) -> 983.4496 | D40: =C40*CHOOSE(B40,$B$8,$B$9,$B$10) -> 29.503488 | E40: =D40*$B$11 -> 17.702093 | F40: =D40*(1-$B$11) -> 11.801395 | G40: =G39*(1-$B$17)+F40 -> 35.028739 | H40: =H39*(1-$B$19)+C40 -> 3125.3481 | I40: =E40*$B$12*(1-$B$15)*(1-$B$14) -> 1286.3566 | J40: =G40*$B$13*(1-$B$14) -> 237.89768 | K40: =H40*CHOOSE(B40,$B$20,$B$21,$B$22)*$B$23 -> 875.09747 | L40: =H40*$B$24*(1-$B$14) -> 531.30918 | M40: =IF(A40<$B$25,0,IF(A40=$B$25,$B$26,M39*(1+$B$27))) -> 0 | N40: =N39*(1-$B$31)+M40 -> 0 | O40: =N40*$B$28 -> 0 | P40: =O40*$B$29 -> 0 | Q40: =I40+J40+K40+L40+P40 -> 2930.661 | R40: =R39+Q40 -> 8349.469
A41: 5 | B41: =ROUNDUP(A41/12,0) -> 1 | C41: =C40*(1+CHOOSE(B41,$B$5,$B$6,$B$7)) -> 1101.4636 | D41: =C41*CHOOSE(B41,$B$8,$B$9,$B$10) -> 33.043907 | E41: =D41*$B$11 -> 19.826344 | F41: =D41*(1-$B$11) -> 13.217563 | G41: =G40*(1-$B$17)+F41 -> 44.743428 | H41: =H40*(1-$B$19)+C41 -> 4070.5442 | I41: =E41*$B$12*(1-$B$15)*(1-$B$14) -> 1440.7194 | J41: =G41*$B$13*(1-$B$14) -> 303.87499 | K41: =H41*CHOOSE(B41,$B$20,$B$21,$B$22)*$B$23 -> 1139.7524 | L41: =H41*$B$24*(1-$B$14) -> 691.99252 | M41: =IF(A41<$B$25,0,IF(A41=$B$25,$B$26,M40*(1+$B$27))) -> 0 | N41: =N40*(1-$B$31)+M41 -> 0 | O41: =N41*$B$28 -> 0 | P41: =O41*$B$29 -> 0 | Q41: =I41+J41+K41+L41+P41 -> 3576.3393 | R41: =R40+Q41 -> 11925.808
A42: 6 | B42: =ROUNDUP(A42/12,0) -> 1 | C42: =C41*(1+CHOOSE(B42,$B$5,$B$6,$B$7)) -> 1233.6392 | D42: =C42*CHOOSE(B42,$B$8,$B$9,$B$10) -> 37.009175 | E42: =D42*$B$11 -> 22.205505 | F42: =D42*(1-$B$11) -> 14.80367 | G42: =G41*(1-$B$17)+F42 -> 55.072755 | H42: =H41*(1-$B$19)+C42 -> 5100.6562 | I42: =E42*$B$12*(1-$B$15)*(1-$B$14) -> 1613.6058 | J42: =G42*$B$13*(1-$B$14) -> 374.02662 | K42: =H42*CHOOSE(B42,$B$20,$B$21,$B$22)*$B$23 -> 1428.1837 | L42: =H42*$B$24*(1-$B$14) -> 867.11156 | M42: =IF(A42<$B$25,0,IF(A42=$B$25,$B$26,M41*(1+$B$27))) -> 0 | N42: =N41*(1-$B$31)+M42 -> 0 | O42: =N42*$B$28 -> 0 | P42: =O42*$B$29 -> 0 | Q42: =I42+J42+K42+L42+P42 -> 4282.9277 | R42: =R41+Q42 -> 16208.736
A43: 7 | B43: =ROUNDUP(A43/12,0) -> 1 | C43: =C42*(1+CHOOSE(B43,$B$5,$B$6,$B$7)) -> 1381.6759 | D43: =C43*CHOOSE(B43,$B$8,$B$9,$B$10) -> 41.450276 | E43: =D43*$B$11 -> 24.870166 | F43: =D43*(1-$B$11) -> 16.580111 | G43: =G42*(1-$B$17)+F43 -> 66.14559 | H43: =H42*(1-$B$19)+C43 -> 6227.2993 | I43: =E43*$B$12*(1-$B$15)*(1-$B$14) -> 1807.2385 | J43: =G43*$B$13*(1-$B$14) -> 449.22778 | K43: =H43*CHOOSE(B43,$B$20,$B$21,$B$22)*$B$23 -> 1743.6438 | L43: =H43*$B$24*(1-$B$14) -> 1058.6409 | M43: =IF(A43<$B$25,0,IF(A43=$B$25,$B$26,M42*(1+$B$27))) -> 0 | N43: =N42*(1-$B$31)+M43 -> 0 | O43: =N43*$B$28 -> 0 | P43: =O43*$B$29 -> 0 | Q43: =I43+J43+K43+L43+P43 -> 5058.7509 | R43: =R42+Q43 -> 21267.487
...
